Workbook

Sheet PT_Region
A3: Row Labels | B3: Sum of Sales | C3: Sum of Profit | D3: Profit Margin %
A4: Central | B4: 501239.89 | C4: 39706.362 | D4: =GETPIVOTDATA("Sum of Profit",$A$3,"Region","Central")/GETPIVOTDATA("Sum of Sales",$A$3,"Region","Central") -> 0.079216286
A5: East | B5: 678781.24 | C5: 91522.78 | D5: =GETPIVOTDATA("Sum of Profit",$A$3,"Region","East")/GETPIVOTDATA("Sum of Sales",$A$3,"Region","East") -> 0.13483399
A6: South | B6: 391721.91 | C6: 46749.43 | D6: =GETPIVOTDATA("Sum of Profit",$A$3,"Region","South")/GETPIVOTDATA("Sum of Sales",$A$3,"Region","South") -> 0.11934342
A7: West | B7: 725457.82 | C7: 108418.45 | D7: =GETPIVOTDATA("Sum of Profit",$A$3,"Region","West")/GETPIVOTDATA("Sum of Sales",$A$3,"Region","West") -> 0.14944831
A8: Grand Total | B8: 2297200.9 | C8: 286397.02

Sheet PT_Category
A3: Row Labels | B3: Sum of Sales | C3: Sum of Profit
A4: Furniture | B4: 741999.8 | C4: 18451.273
A5: Office Supplies | B5: 719047.03 | C5: 122490.8
A6: Technology | B6: 836154.03 | C6: 145454.95
A7: Grand Total | B7: 2297200.9 | C7: 286397.02

Sheet PT_MonthlyTrend
A3: Row Labels | B3: Sum of Sales
A4: 2014 | B4: 484247.5
A5: Jan | B5: 14236.895
A6: Feb | B6: 4519.892
A7: Mar | B7: 55691.009
A8: Apr | B8: 28295.345
A9: May | B9: 23648.287
A10: Jun | B10: 34595.128
A11: Jul | B11: 33946.393
A12: Aug | B12: 27909.468
A13: Sep | B13: 81777.351
A14: Oct | B14: 31453.393
A15: Nov | B15: 78628.717
A16: Dec | B16: 69545.62
A17: 2015 | B17: 470532.51
A18: Jan | B18: 18174.076
A19: Feb | B19: 11951.411
A20: Mar | B20: 38726.252
A21: Apr | B21: 34195.208
A22: May | B22: 30131.686
A23: Jun | B23: 24797.292
A24: Jul | B24: 28765.325
A25: Aug | B25: 36898.332
A26: Sep | B26: 64595.918
A27: Oct | B27: 31404.924
A28: Nov | B28: 75972.564
A29: Dec | B29: 74919.521
A30: 2016 | B30: 609205.6
A31: Jan | B31: 18542.491
A32: Feb | B32: 22978.815
A33: Mar | B33: 51715.875
A34: Apr | B34: 38750.039
A35: May | B35: 56987.728
A36: Jun | B36: 40344.534
A37: Jul | B37: 39261.963
A38: Aug | B38: 31115.374
A39: Sep | B39: 73410.025
A40: Oct | B40: 59687.745
A41: Nov | B41: 79411.966
A42: Dec | B42: 96999.043
...

Sheet PT_TopBottomProducts
A3: Row Labels | B3: Sum of Sales | C3: Sum of Profit
A4: Canon imageCLASS 2200 Advanced Copier | B4: 61599.824 | C4: 25199.928
A5: Cisco TelePresence System EX90 Videoconferencing Unit | B5: 22638.48 | C5: -1811.0784
A6: Fellowes PB500 Electric Punch Plastic Comb Binding Machine with Manual Bind | B6: 27453.384 | C6: 7753.039
A7: GBC DocuBind P400 Electric Binding System | B7: 17965.068 | C7: -1878.1662
A8: GBC DocuBind TL300 Electric Binding System | B8: 19823.479 | C8: 2233.5051
A9: GBC Ibimaster 500 Manual ProClick Binding System | B9: 19024.5 | C9: 760.98
A10: Hewlett Packard LaserJet 3310 Copier | B10: 18839.686 | C10: 6983.8836
A11: High Speed Automatic Electric Letter Opener | B11: 17030.312 | C11: -262.0048
A12: HON 5400 Series Task Chairs for Big and Tall | B12: 21870.576 | C12: 0
A13: HP Designjet T520 Inkjet Large Format Printer - 24" Color | B13: 18374.895 | C13: 4094.9766
A14: Grand Total | B14: 244620.2 | C14: 43075.063

Sheet PT_Segment
A3: Row Labels | B3: Sum of Sales | C3: Sum of Profit | D3: Count of Order ID
A4: Consumer | B4: 1161401.3 | C4: 134119.21 | D4: 5191
A5: Corporate | B5: 706146.37 | C5: 91979.134 | D5: 3020
A6: Home Office | B6: 429653.15 | C6: 60298.679 | D6: 1783
A7: Grand Total | B7: 2297200.9 | C7: 286397.02 | D7: 9994

Sheet Raw_Data
A1: Row ID | B1: Order ID | C1: Order Date | D1: Ship Date | E1: Ship Mode | F1: Customer ID | G1: Customer Name | H1: Segment | I1: Country | J1: City | K1: State | L1: Postal Code | M1: Region | N1: Product ID | O1: Category | P1: Sub-Category | Q1: Product Name | R1: Sales | S1: Quantity | T1: Discount | U1: Profit | V1: Order Year | W1: Order Month | X1: Profit Margin % | Y1: Shipping Duration (days)
A2: 1 | B2: CA-2016-152156 | C2: 42682 | D2: 42685 | E2: Second Class | F2: CG-12520 | G2: Claire Gute | H2: Consumer | I2: United States | J2: Henderson | K2: Kentucky | L2: 42420 | M2: South | N2: FUR-BO-10001798 | O2: Furniture | P2: Bookcases | Q2: Bush Somerset Collection Bookcase | R2: 261.96 | S2: 2 | T2: 0 | U2: 41.9136 | V2: =YEAR(C2) -> 2016 | W2: =TEXT(C2,"mmm") -> Nov | X2: =U2/R2 -> 0.16 | Y2: =D2-C2 -> 3
A3: 2 | B3: CA-2016-152156 | C3: 42682 | D3: 42685 | E3: Second Class | F3: CG-12520 | G3: Claire Gute | H3: Consumer | I3: United States | J3: Henderson | K3: Kentucky | L3: 42420 | M3: South | N3: FUR-CH-10000454 | O3: Furniture | P3: Chairs | Q3: Hon Deluxe Fabric Upholstered Stacking Chairs, Rounded Back | R3: 731.94 | S3: 3 | T3: 0 | U3: 219.582 | V3: =YEAR(C3) -> 2016 | W3: =TEXT(C3,"mmm") -> Nov | X3: =U3/R3 -> 0.3 | Y3: =D3-C3 -> 3
A4: 3 | B4: CA-2016-138688 | C4: 42533 | D4: 42537 | E4: Second Class | F4: DV-13045 | G4: Darrin Van Huff | H4: Corporate | I4: United States | J4: Los Angeles | K4: California | L4: 90036 | M4: West | N4: OFF-LA-10000240 | O4: Office Supplies | P4: Labels | Q4: Self-Adhesive Address Labels for Typewriters by Universal | R4: 14.62 | S4: 2 | T4: 0 | U4: 6.8714 | V4: =YEAR(C4) -> 2016 | W4: =TEXT(C4,"mmm") -> Jun | X4: =U4/R4 -> 0.47 | Y4: =D4-C4 -> 4
A5: 4 | B5: US-2015-108966 | C5: 42288 | D5: 42295 | E5: Standard Class | F5: SO-20335 | G5: Sean O'Donnell | H5: Consumer | I5: United States | J5: Fort Lauderdale | K5: Florida | L5: 33311 | M5: South | N5: FUR-TA-10000577 | O5: Furniture | P5: Tables | Q5: Bretford CR4500 Series Slim Rectangular Table | R5: 957.5775 | S5: 5 | T5: 0.45 | U5: -383.031 | V5: =YEAR(C5) -> 2015 | W5: =TEXT(C5,"mmm") -> Oct | X5: =U5/R5 -> -0.4 | Y5: =D5-C5 -> 7
A6: 5 | B6: US-2015-108966 | C6: 42288 | D6: 42295 | E6: Standard Class | F6: SO-20335 | G6: Sean O'Donnell | H6: Consumer | I6: United States | J6: Fort Lauderdale | K6: Florida | L6: 33311 | M6: South | N6: OFF-ST-10000760 | O6: Office Supplies | P6: Storage | Q6: Eldon Fold 'N Roll Cart System | R6: 22.368 | S6: 2 | T6: 0.2 | U6: 2.5164 | V6: =YEAR(C6) -> 2015 | W6: =TEXT(C6,"mmm") -> Oct | X6: =U6/R6 -> 0.1125 | Y6: =D6-C6 -> 7
A7: 6 | B7: CA-2014-115812 | C7: 41799 | D7: 41804 | E7: Standard Class | F7: BH-11710 | G7: Brosina Hoffman | H7: Consumer | I7: United States | J7: Los Angeles | K7: California | L7: 90032 | M7: West | N7: FUR-FU-10001487 | O7: Furniture | P7: Furnishings | Q7: Eldon Expressions Wood and Plastic Desk Accessories, Cherry Wood | R7: 48.86 | S7: 7 | T7: 0 | U7: 14.1694 | V7: =YEAR(C7) -> 2014 | W7: =TEXT(C7,"mmm") -> Jun | X7: =U7/R7 -> 0.29 | Y7: =D7-C7 -> 5
A8: 7 | B8: CA-2014-115812 | C8: 41799 | D8: 41804 | E8: Standard Class | F8: BH-11710 | G8: Brosina Hoffman | H8: Consumer | I8: United States | J8: Los Angeles | K8: California | L8: 90032 | M8: West | N8: OFF-AR-10002833 | O8: Office Supplies | P8: Art | Q8: Newell 322 | R8: 7.28 | S8: 4 | T8: 0 | U8: 1.9656 | V8: =YEAR(C8) -> 2014 | W8: =TEXT(C8,"mmm") -> Jun | X8: =U8/R8 -> 0.27 | Y8: =D8-C8 -> 5
A9: 8 | B9: CA-2014-115812 | C9: 41799 | D9: 41804 | E9: Standard Class | F9: BH-11710 | G9: Brosina Hoffman | H9: Consumer | I9: United States | J9: Los Angeles | K9: California | L9: 90032 | M9: West | N9: TEC-PH-10002275 | O9: Technology | P9: Phones | Q9: Mitel 5320 IP Phone VoIP phone | R9: 907.152 | S9: 6 | T9: 0.2 | U9: 90.7152 | V9: =YEAR(C9) -> 2014 | W9: =TEXT(C9,"mmm") -> Jun | X9: =U9/R9 -> 0.1 | Y9: =D9-C9 -> 5
A10: 9 | B10: CA-2014-115812 | C10: 41799 | D10: 41804 | E10: Standard Class | F10: BH-11710 | G10: Brosina Hoffman | H10: Consumer | I10: United States | J10: Los Angeles | K10: California | L10: 90032 | M10: West | N10: OFF-BI-10003910 | O10: Office Supplies | P10: Binders | Q10: DXL Angle-View Binders with Locking Rings by Samsill | R10: 18.504 | S10: 3 | T10: 0.2 | U10: 5.7825 | V10: =YEAR(C10) -> 2014 | W10: =TEXT(C10,"mmm") -> Jun | X10: =U10/R10 -> 0.3125 | Y10: =D10-C10 -> 5
A11: 10 | B11: CA-2014-115812 | C11: 41799 | D11: 41804 | E11: Standard Class | F11: BH-11710 | G11: Brosina Hoffman | H11: Consumer | I11: United States | J11: Los Angeles | K11: California | L11: 90032 | M11: West | N11: OFF-AP-10002892 | O11: Office Supplies | P11: Appliances | Q11: Belkin F5C206VTEL 6 Outlet Surge | R11: 114.9 | S11: 5 | T11: 0 | U11: 34.47 | V11: =YEAR(C11) -> 2014 | W11: =TEXT(C11,"mmm") -> Jun | X11: =U11/R11 -> 0.3 | Y11: =D11-C11 -> 5
A12: 11 | B12: CA-2014-115812 | C12: 41799 | D12: 41804 | E12: Standard Class | F12: BH-11710 | G12: Brosina Hoffman | H12: Consumer | I12: United States | J12: Los Angeles | K12: California | L12: 90032 | M12: West | N12: FUR-TA-10001539 | O12: Furniture | P12: Tables | Q12: Chromcraft Rectangular Conference Tables | R12: 1706.184 | S12: 9 | T12: 0.2 | U12: 85.3092 | V12: =YEAR(C12) -> 2014 | W12: =TEXT(C12,"mmm") -> Jun | X12: =U12/R12 -> 0.05 | Y12: =D12-C12 -> 5
A13: 12 | B13: CA-2014-115812 | C13: 41799 | D13: 41804 | E13: Standard Class | F13: BH-11710 | G13: Brosina Hoffman | H13: Consumer | I13: United States | J13: Los Angeles | K13: California | L13: 90032 | M13: West | N13: TEC-PH-10002033 | O13: Technology | P13: Phones | Q13: Konftel 250 Conference phone - Charcoal black | R13: 911.424 | S13: 4 | T13: 0.2 | U13: 68.3568 | V13: =YEAR(C13) -> 2014 | W13: =TEXT(C13,"mmm") -> Jun | X13: =U13/R13 -> 0.075 | Y13: =D13-C13 -> 5
... A9995: 9994 | B9995: CA-2017-119914 | C9995: 42859 | D9995: 42864 | E9995: Second Class | F9995: CC-12220 | G9995: Chris Cortes | H9995: Consumer | I9995: United States | J9995: Westminster | K9995: California | L9995: 92683 | M9995: West | N9995: OFF-AP-10002684 | O9995: Office Supplies | P9995: Appliances | Q9995: Acco 7-Outlet Masterpiece Power Center, Wihtout Fax/Phone Line Protection | R9995: 243.16 | S9995: 2 | T9995: 0 | U9995: 72.948 | V9995: =YEAR(C9995) -> 2017 | W9995: =TEXT(C9995,"mmm") -> May | X9995: =U9995/R9995 -> 0.3 | Y9995: =D9995-C9995 -> 5

Sheet Data_check
A1: Check | B1: Result
A2: Number of Rows | B2: =COUNTA(Raw_Data!A2:A9995) -> 9994
A3: Number of Columns | B3: =COUNTA(Raw_Data!A1:U1) -> 21
A4: Missing values | B4: =COUNTBLANK(Raw_Data!A2:U9995) -> 0
A5: Duplicate Rows | B5: {=SUMPRODUCT((COUNTIFS(Raw_Data!B2:B9995,Raw_Data!B2:B9995,Raw_Data!N2:N9995,Raw_Data!N2:N9995)>1)*1)} -> 16
A6: Earliest Order Date | B6: =MIN(Raw_Data!C2:C9995) -> 41642
A7: Latest Order Date | B7: =MAX(Raw_Data!C2:C9995) -> 43099
A8: Date Range(Days) | B8: =B7-B6 -> 1457
A9: Unique Customers | B9: =COUNTA(_xlfn.UNIQUE(Raw_Data!F2:F9995)) -> 793
A10: Unique Products | B10: =COUNTA(_xlfn.UNIQUE(Raw_Data!N2:N9995)) -> 1862
A11: Total Sales | B11: =SUM(Raw_Data!R2:R9995) -> 2297200.9
A12: Total profit | B12: =SUM(Raw_Data!U2:U9995) -> 286397.02
